Workbook

Sheet Dashboard
A1: WHEY PROTEIN SALES — 2024 PERFORMANCE DASHBOARD
A3: Jan – Aug 2024 | 1,500 transactions across 27 brands, 5 categories & 7 customer-channel types | Cleaned, modeled & analyzed by Dattaprasad Tawate
B4: Channel: | C4: Gym Pro Shop | F4: Category: | G4: Hydrolised | J4: Month: | K4: Feb
A5: NET REVENUE | C5: AT-RISK REVENUE | E5: AT-RISK % | G5: TOTAL TRANSACTIONS | I5: UNIQUE CUSTOMERS | K5: REPEAT PURCHASE RATE | M5: AVG ORDER VALUE
A6: =Analysis!B64 -> 0 | C6: =Analysis!B66 -> 0 | E6: =Analysis!B67 -> 0 | G6: =Analysis!B68 -> 0 | I6: =Analysis!B69 -> 1387 | K6: =Analysis!B71 -> 0.059120404 | M6: =Analysis!B72 -> 0

Sheet Insights
A1: WHEY PROTEIN SALES — INSIGHTS & RECOMMENDATIONS
A2: Self-directed analytics project | Jan-Aug 2024 | 1,500 transactions, 1,387 customers | Dattaprasad Tawate
A4: 1. Revenue Quality: Gross vs Net
A5: Business Insight
A6: Gross revenue across all 1,500 transactions is ₹94.8L, but ₹9.8L of that (10.4%) sits in Cancelled, Refunded, or Returned orders and never converts to real revenue. Net (Delivered) revenue is ₹85.0L. A double-digit at-risk rate on a repeat-purchase consumable is high enough to investigate by category and channel rather than write off as background noise.
A8: 2. Retention Is the Real Problem
A9: Risk / Corrective Insight
A10: Of 1,387 unique customers, only 82 (5.9%) placed more than one order. For a consumable that should be reordered every 4-8 weeks, a 94% one-time-buyer rate points to a retention failure rather than an acquisition problem — the brand is spending to acquire customers who never come back. This mirrors the 37% one-time-buyer churn signal found independently in the companion SQL analytics project on the same product category, which strengthens confidence that this is a real pattern rather than a quirk of one dataset. Recommended action: a reorder-reminder trigger around day 25-35 post-purchase, targeted first at the End User segment where order volume is highest.
A12: 3. Customer Channel Mix
A13: Business Insight
A14: End User (direct consumer) is the largest channel by both order count (361 transactions) and revenue (₹21.2L), and also carries the highest average order value (₹5,881) of all seven channel types. Shop Owner is a close second by volume (332 transactions, ₹18.8L). The B2B-style channels — Trainer, Promoter, Gym Pro Shop — bring in meaningful volume but a slightly lower AOV, suggesting the direct-to-consumer relationship is currently the most valuable one to protect and grow, not just the largest.
A16: 4. Category & Pack Size
... A30: The source data had the inconsistencies typical of real operational exports: customer-channel labels with typos and duplicate spellings ('Enduser' vs 'End user ', 'Master tainer', 'influncer', 'Gym Pro sop'), brand names with inconsistent casing and trailing whitespace, city names split across case variants (and 'Bangalore' vs its official name 'Bengaluru'), and an age-segment label ('Teenager') that actually covered ages 18-29. All of this was standardized in the Data sheet before any analysis was run — see the notes column on that sheet for the full mapping. Every KPI and chart in this workbook is formula-driven (SUMIFS/COUNTIFS/SUMPRODUCT) off the cleaned table, so it recalculates automatically if the underlying data changes.

Sheet Analysis
A1: ANALYSIS ENGINE (formula-driven — feeds Dashboard charts & KPI cards) | D1: =IF(Dashboard!$C$4="All","*",Dashboard!$C$4) -> Gym Pro Shop | E1: =IF(Dashboard!$G$4="All","*",Dashboard!$G$4) -> Hydrolised | F1: =IF(Dashboard!$K$4="All","*",Dashboard!$K$4) -> Feb
A3: Month | B3: Net Revenue | C3: Gross Revenue | D3: Transactions | E3: Units Sold
A4: Jan | B4: =SUMIFS(Data!$R$2:$R$1501, Data!$H$2:$H$1501, A4, Data!$J$2:$J$1501, $D$1, Data!$L$2:$L$1501, $E$1) -> 0 | C4: =SUMIFS(Data!$P$2:$P$1501, Data!$H$2:$H$1501, A4, Data!$J$2:$J$1501, $D$1, Data!$L$2:$L$1501, $E$1) -> 0 | D4: =COUNTIFS(Data!$H$2:$H$1501, A4, Data!$J$2:$J$1501, $D$1, Data!$L$2:$L$1501, $E$1) -> 0 | E4: =SUMIFS(Data!$N$2:$N$1501, Data!$H$2:$H$1501, A4, Data!$J$2:$J$1501, $D$1, Data!$L$2:$L$1501, $E$1) -> 0
A5: Feb | B5: =SUMIFS(Data!$R$2:$R$1501, Data!$H$2:$H$1501, A5, Data!$J$2:$J$1501, $D$1, Data!$L$2:$L$1501, $E$1) -> 0 | C5: =SUMIFS(Data!$P$2:$P$1501, Data!$H$2:$H$1501, A5, Data!$J$2:$J$1501, $D$1, Data!$L$2:$L$1501, $E$1) -> 0 | D5: =COUNTIFS(Data!$H$2:$H$1501, A5, Data!$J$2:$J$1501, $D$1, Data!$L$2:$L$1501, $E$1) -> 0 | E5: =SUMIFS(Data!$N$2:$N$1501, Data!$H$2:$H$1501, A5, Data!$J$2:$J$1501, $D$1, Data!$L$2:$L$1501, $E$1) -> 0
A6: Mar | B6: =SUMIFS(Data!$R$2:$R$1501, Data!$H$2:$H$1501, A6, Data!$J$2:$J$1501, $D$1, Data!$L$2:$L$1501, $E$1) -> 0 | C6: =SUMIFS(Data!$P$2:$P$1501, Data!$H$2:$H$1501, A6, Data!$J$2:$J$1501, $D$1, Data!$L$2:$L$1501, $E$1) -> 0 | D6: =COUNTIFS(Data!$H$2:$H$1501, A6, Data!$J$2:$J$1501, $D$1, Data!$L$2:$L$1501, $E$1) -> 0 | E6: =SUMIFS(Data!$N$2:$N$1501, Data!$H$2:$H$1501, A6, Data!$J$2:$J$1501, $D$1, Data!$L$2:$L$1501, $E$1) -> 0
A7: Apr | B7: =SUMIFS(Data!$R$2:$R$1501, Data!$H$2:$H$1501, A7, Data!$J$2:$J$1501, $D$1, Data!$L$2:$L$1501, $E$1) -> 0 | C7: =SUMIFS(Data!$P$2:$P$1501, Data!$H$2:$H$1501, A7, Data!$J$2:$J$1501, $D$1, Data!$L$2:$L$1501, $E$1) -> 0 | D7: =COUNTIFS(Data!$H$2:$H$1501, A7, Data!$J$2:$J$1501, $D$1, Data!$L$2:$L$1501, $E$1) -> 0 | E7: =SUMIFS(Data!$N$2:$N$1501, Data!$H$2:$H$1501, A7, Data!$J$2:$J$1501, $D$1, Data!$L$2:$L$1501, $E$1) -> 0
A8: May | B8: =SUMIFS(Data!$R$2:$R$1501, Data!$H$2:$H$1501, A8, Data!$J$2:$J$1501, $D$1, Data!$L$2:$L$1501, $E$1) -> 0 | C8: =SUMIFS(Data!$P$2:$P$1501, Data!$H$2:$H$1501, A8, Data!$J$2:$J$1501, $D$1, Data!$L$2:$L$1501, $E$1) -> 0 | D8: =COUNTIFS(Data!$H$2:$H$1501, A8, Data!$J$2:$J$1501, $D$1, Data!$L$2:$L$1501, $E$1) -> 0 | E8: =SUMIFS(Data!$N$2:$N$1501, Data!$H$2:$H$1501, A8, Data!$J$2:$J$1501, $D$1, Data!$L$2:$L$1501, $E$1) -> 0
A9: Jun | B9: =SUMIFS(Data!$R$2:$R$1501, Data!$H$2:$H$1501, A9, Data!$J$2:$J$1501, $D$1, Data!$L$2:$L$1501, $E$1) -> 0 | C9: =SUMIFS(Data!$P$2:$P$1501, Data!$H$2:$H$1501, A9, Data!$J$2:$J$1501, $D$1, Data!$L$2:$L$1501, $E$1) -> 12600 | D9: =COUNTIFS(Data!$H$2:$H$1501, A9, Data!$J$2:$J$1501, $D$1, Data!$L$2:$L$1501, $E$1) -> 2 | E9: =SUMIFS(Data!$N$2:$N$1501, Data!$H$2:$H$1501, A9, Data!$J$2:$J$1501, $D$1, Data!$L$2:$L$1501, $E$1) -> 11
A10: Jul | B10: =SUMIFS(Data!$R$2:$R$1501, Data!$H$2:$H$1501, A10, Data!$J$2:$J$1501, $D$1, Data!$L$2:$L$1501, $E$1) -> 192200 | C10: =SUMIFS(Data!$P$2:$P$1501, Data!$H$2:$H$1501, A10, Data!$J$2:$J$1501, $D$1, Data!$L$2:$L$1501, $E$1) -> 205000 | D10: =COUNTIFS(Data!$H$2:$H$1501, A10, Data!$J$2:$J$1501, $D$1, Data!$L$2:$L$1501, $E$1) -> 31 | E10: =SUMIFS(Data!$N$2:$N$1501, Data!$H$2:$H$1501, A10, Data!$J$2:$J$1501, $D$1, Data!$L$2:$L$1501, $E$1) -> 528
A11: Aug | B11: =SUMIFS(Data!$R$2:$R$1501, Data!$H$2:$H$1501, A11, Data!$J$2:$J$1501, $D$1, Data!$L$2:$L$1501, $E$1) -> 0 | C11: =SUMIFS(Data!$P$2:$P$1501, Data!$H$2:$H$1501, A11, Data!$J$2:$J$1501, $D$1, Data!$L$2:$L$1501, $E$1) -> 0 | D11: =COUNTIFS(Data!$H$2:$H$1501, A11, Data!$J$2:$J$1501, $D$1, Data!$L$2:$L$1501, $E$1) -> 0 | E11: =SUMIFS(Data!$N$2:$N$1501, Data!$H$2:$H$1501, A11, Data!$J$2:$J$1501, $D$1, Data!$L$2:$L$1501, $E$1) -> 0
A14: Customer Channel | B14: Transactions | C14: Net Revenue | D14: AOV
A15: End User | B15: =COUNTIFS(Data!$J$2:$J$1501, A15, Data!$L$2:$L$1501, $E$1, Data!$H$2:$H$1501, $F$1) -> 3 | C15: =SUMIFS(Data!$R$2:$R$1501, Data!$J$2:$J$1501, A15, Data!$L$2:$L$1501, $E$1, Data!$H$2:$H$1501, $F$1) -> 11000 | D15: =IF(B15=0, 0, C15/B15) -> 3666.6667
A16: Shop Owner | B16: =COUNTIFS(Data!$J$2:$J$1501, A16, Data!$L$2:$L$1501, $E$1, Data!$H$2:$H$1501, $F$1) -> 0 | C16: =SUMIFS(Data!$R$2:$R$1501, Data!$J$2:$J$1501, A16, Data!$L$2:$L$1501, $E$1, Data!$H$2:$H$1501, $F$1) -> 0 | D16: =IF(B16=0, 0, C16/B16) -> 0
A17: Master Trainer | B17: =COUNTIFS(Data!$J$2:$J$1501, A17, Data!$L$2:$L$1501, $E$1, Data!$H$2:$H$1501, $F$1) -> 3 | C17: =SUMIFS(Data!$R$2:$R$1501, Data!$J$2:$J$1501, A17, Data!$L$2:$L$1501, $E$1, Data!$H$2:$H$1501, $F$1) -> 17700 | D17: =IF(B17=0, 0, C17/B17) -> 5900
A18: Trainer | B18: =COUNTIFS(Data!$J$2:$J$1501, A18, Data!$L$2:$L$1501, $E$1, Data!$H$2:$H$1501, $F$1) -> 27 | C18: =SUMIFS(Data!$R$2:$R$1501, Data!$J$2:$J$1501, A18, Data!$L$2:$L$1501, $E$1, Data!$H$2:$H$1501, $F$1) -> 160000 | D18: =IF(B18=0, 0, C18/B18) -> 5925.9259
A19: Gym Pro Shop | B19: =COUNTIFS(Data!$J$2:$J$1501, A19, Data!$L$2:$L$1501, $E$1, Data!$H$2:$H$1501, $F$1) -> 0 | C19: =SUMIFS(Data!$R$2:$R$1501, Data!$J$2:$J$1501, A19, Data!$L$2:$L$1501, $E$1, Data!$H$2:$H$1501, $F$1) -> 0 | D19: =IF(B19=0, 0, C19/B19) -> 0
A20: Influencer | B20: =COUNTIFS(Data!$J$2:$J$1501, A20, Data!$L$2:$L$1501, $E$1, Data!$H$2:$H$1501, $F$1) -> 9 | C20: =SUMIFS(Data!$R$2:$R$1501, Data!$J$2:$J$1501, A20, Data!$L$2:$L$1501, $E$1, Data!$H$2:$H$1501, $F$1) -> 52400 | D20: =IF(B20=0, 0, C20/B20) -> 5822.2222
A21: Promoter | B21: =COUNTIFS(Data!$J$2:$J$1501, A21, Data!$L$2:$L$1501, $E$1, Data!$H$2:$H$1501, $F$1) -> 21 | C21: =SUMIFS(Data!$R$2:$R$1501, Data!$J$2:$J$1501, A21, Data!$L$2:$L$1501, $E$1, Data!$H$2:$H$1501, $F$1) -> 97700 | D21: =IF(B21=0, 0, C21/B21) -> 4652.381
A24: Category | B24: Net Revenue | C24: Units Sold | D24: % of Net Revenue
A25: Isolate | B25: =SUMIFS(Data!$R$2:$R$1501, Data!$L$2:$L$1501, A25, Data!$J$2:$J$1501, $D$1, Data!$H$2:$H$1501, $F$1) -> 13200 | C25: =SUMIFS(Data!$N$2:$N$1501, Data!$L$2:$L$1501, A25, Data!$J$2:$J$1501, $D$1, Data!$H$2:$H$1501, $F$1) -> 11 | D25: =IF($B$64=0, 0, B25/$B$64) -> 0
A26: Hydrolised | B26: =SUMIFS(Data!$R$2:$R$1501, Data!$L$2:$L$1501, A26, Data!$J$2:$J$1501, $D$1, Data!$H$2:$H$1501, $F$1) -> 0 | C26: =SUMIFS(Data!$N$2:$N$1501, Data!$L$2:$L$1501, A26, Data!$J$2:$J$1501, $D$1, Data!$H$2:$H$1501, $F$1) -> 0 | D26: =IF($B$64=0, 0, B26/$B$64) -> 0
A27: Concentrate | B27: =SUMIFS(Data!$R$2:$R$1501, Data!$L$2:$L$1501, A27, Data!$J$2:$J$1501, $D$1, Data!$H$2:$H$1501, $F$1) -> 178400 | C27: =SUMIFS(Data!$N$2:$N$1501, Data!$L$2:$L$1501, A27, Data!$J$2:$J$1501, $D$1, Data!$H$2:$H$1501, $F$1) -> 283 | D27: =IF($B$64=0, 0, B27/$B$64) -> 0
A28: Blend | B28: =SUMIFS(Data!$R$2:$R$1501, Data!$L$2:$L$1501, A28, Data!$J$2:$J$1501, $D$1, Data!$H$2:$H$1501, $F$1) -> 0 | C28: =SUMIFS(Data!$N$2:$N$1501, Data!$L$2:$L$1501, A28, Data!$J$2:$J$1501, $D$1, Data!$H$2:$H$1501, $F$1) -> 0 | D28: =IF($B$64=0, 0, B28/$B$64) -> 0
A29: Gainer | B29: =SUMIFS(Data!$R$2:$R$1501, Data!$L$2:$L$1501, A29, Data!$J$2:$J$1501, $D$1, Data!$H$2:$H$1501, $F$1) -> 0 | C29: =SUMIFS(Data!$N$2:$N$1501, Data!$L$2:$L$1501, A29, Data!$J$2:$J$1501, $D$1, Data!$H$2:$H$1501, $F$1) -> 0 | D29: =IF($B$64=0, 0, B29/$B$64) -> 0
A32: City | B32: Net Revenue
A33: Bengaluru | B33: =SUMIFS(Data!$R$2:$R$1501, Data!$Q$2:$Q$1501, A33, Data!$J$2:$J$1501, $D$1, Data!$L$2:$L$1501, $E$1, Data!$H$2:$H$1501, $F$1) -> 0
A34: Hyderabad | B34: =SUMIFS(Data!$R$2:$R$1501, Data!$Q$2:$Q$1501, A34, Data!$J$2:$J$1501, $D$1, Data!$L$2:$L$1501, $E$1, Data!$H$2:$H$1501, $F$1) -> 0
A35: New Delhi | B35: =SUMIFS(Data!$R$2:$R$1501, Data!$Q$2:$Q$1501, A35, Data!$J$2:$J$1501, $D$1, Data!$L$2:$L$1501, $E$1, Data!$H$2:$H$1501, $F$1) -> 0
A36: Chennai | B36: =SUMIFS(Data!$R$2:$R$1501, Data!$Q$2:$Q$1501, A36, Data!$J$2:$J$1501, $D$1, Data!$L$2:$L$1501, $E$1, Data!$H$2:$H$1501, $F$1) -> 0
A37: Mumbai | B37: =SUMIFS(Data!$R$2:$R$1501, Data!$Q$2:$Q$1501, A37, Data!$J$2:$J$1501, $D$1, Data!$L$2:$L$1501, $E$1, Data!$H$2:$H$1501, $F$1) -> 0
A38: Kolkata | B38: =SUMIFS(Data!$R$2:$R$1501, Data!$Q$2:$Q$1501, A38, Data!$J$2:$J$1501, $D$1, Data!$L$2:$L$1501, $E$1, Data!$H$2:$H$1501, $F$1) -> 0
A39: Pune | B39: =SUMIFS(Data!$R$2:$R$1501, Data!$Q$2:$Q$1501, A39, Data!$J$2:$J$1501, $D$1, Data!$L$2:$L$1501, $E$1, Data!$H$2:$H$1501, $F$1) -> 0
A40: Lucknow | B40: =SUMIFS(Data!$R$2:$R$1501, Data!$Q$2:$Q$1501, A40, Data!$J$2:$J$1501, $D$1, Data!$L$2:$L$1501, $E$1, Data!$H$2:$H$1501, $F$1) -> 0
A41: Navi Mumbai | B41: =SUMIFS(Data!$R$2:$R$1501, Data!$Q$2:$Q$1501, A41, Data!$J$2:$J$1501, $D$1, Data!$L$2:$L$1501, $E$1, Data!$H$2:$H$1501, $F$1) -> 0
A42: Gurugram | B42: =SUMIFS(Data!$R$2:$R$1501, Data!$Q$2:$Q$1501, A42, Data!$J$2:$J$1501, $D$1, Data!$L$2:$L$1501, $E$1, Data!$H$2:$H$1501, $F$1) -> 0
A44: Age Segment | B44: Men Revenue | C44: Women Revenue
A45: 18-29 | B45: =SUMIFS(Data!$R$2:$R$1501, Data!$F$2:$F$1501, A45, Data!$D$2:$D$1501, "Men", Data!$J$2:$J$1501, $D$1, Data!$L$2:$L$1501, $E$1, Data!$H$2:$H$1501, $F$1) -> 0 | C45: =SUMIFS(Data!$R$2:$R$1501, Data!$F$2:$F$1501, A45, Data!$D$2:$D$1501, "Women", Data!$J$2:$J$1501, $D$1, Data!$L$2:$L$1501, $E$1, Data!$H$2:$H$1501, $F$1) -> 0
A46: 30-49 | B46: =SUMIFS(Data!$R$2:$R$1501, Data!$F$2:$F$1501, A46, Data!$D$2:$D$1501, "Men", Data!$J$2:$J$1501, $D$1, Data!$L$2:$L$1501, $E$1, Data!$H$2:$H$1501, $F$1) -> 0 | C46: =SUMIFS(Data!$R$2:$R$1501, Data!$F$2:$F$1501, A46, Data!$D$2:$D$1501, "Women", Data!$J$2:$J$1501, $D$1, Data!$L$2:$L$1501, $E$1, Data!$H$2:$H$1501, $F$1) -> 0
A47: 50+ | B47: =SUMIFS(Data!$R$2:$R$1501, Data!$F$2:$F$1501, A47, Data!$D$2:$D$1501, "Men", Data!$J$2:$J$1501, $D$1, Data!$L$2:$L$1501, $E$1, Data!$H$2:$H$1501, $F$1) -> 0 | C47: =SUMIFS(Data!$R$2:$R$1501, Data!$F$2:$F$1501, A47, Data!$D$2:$D$1501, "Women", Data!$J$2:$J$1501, $D$1, Data!$L$2:$L$1501, $E$1, Data!$H$2:$H$1501, $F$1) -> 0
A51: Order Status | B51: Count | C51: Gross Amount | D51: % of Gross
...

Sheet Data
A1: Line # | B1: Order ID | C1: Customer ID | D1: Gender | E1: Age | F1: Age Segment | G1: Order Date | H1: Month | I1: Order Status | J1: Customer Channel | K1: Brand | L1: Category | M1: Pack Size | N1: Quantity | O1: Currency | P1: Amount (INR) | Q1: Ship City | R1: Net Revenue | S1: Customer Type | U1: Data cleaning notes
A2: 1 | B2: 171-1029312-3038738 | C2: 1029312 | D2: Men | E2: 44 | F2: 30-49 | G2: 45295 | H2: Jan | I2: Delivered | J2: End User | K2: Proquest | L2: Isolate | M2: 1KG | N2: 9 | O2: INR | P2: 6500 | Q2: Mohali | R2: =IF(I2="Delivered",P2,0) -> 6500 | S2: =IF(COUNTIF($C$2:$C$1501,C2)>1,"Repeat","One-Time") -> One-Time | U2: - Customer Channel: corrected typos/inconsistent labels (e.g. 'Enduser'/'End user' -> 'End User', 'Master tainer' -> 'Master Trainer', 'influncer' -> 'Influencer', 'Gym Pro sop' -> 'Gym Pro Shop').
A3: 2 | B3: 405-2183842-2225946 | C3: 2183842 | D3: Men | E3: 29 | F3: 18-29 | G3: 45296 | H3: Jan | I3: Delivered | J3: End User | K3: Big Muscle | L3: Isolate | M3: 2KG | N3: 7 | O3: INR | P3: 6500 | Q3: Gurugram | R3: =IF(I3="Delivered",P3,0) -> 6500 | S3: =IF(COUNTIF($C$2:$C$1501,C3)>1,"Repeat","One-Time") -> One-Time | U3: - Brand: trimmed whitespace and standardized casing (e.g. 'Bpi'/'BPI' -> 'BPI', 'Avatar '/'Avatar' -> 'Avatar').
A4: 3 | B4: 171-1641533-8921966 | C4: 1641533 | D4: Men | E4: 67 | F4: 50+ | G4: 45297 | H4: Jan | I4: Delivered | J4: End User | K4: Venkys | L4: Isolate | M4: 1KG | N4: 6 | O4: INR | P4: 6500 | Q4: Kolkata | R4: =IF(I4="Delivered",P4,0) -> 6500 | S4: =IF(COUNTIF($C$2:$C$1501,C4)>1,"Repeat","One-Time") -> One-Time | U4: - Ship City: trimmed, standardized case, and merged 'Bangalore' into 'Bengaluru' (official city name since 2014).
A5: 4 | B5: 404-7490807-6300351 | C5: 7490807 | D5: Men | E5: 20 | F5: 18-29 | G5: 45298 | H5: Jan | I5: Delivered | J5: End User | K5: Core Nutrition | L5: Isolate | M5: 1KG | N5: 2 | O5: INR | P5: 6500 | Q5: Thanjavur | R5: =IF(I5="Delivered",P5,0) -> 6500 | S5: =IF(COUNTIF($C$2:$C$1501,C5)>1,"Repeat","One-Time") -> One-Time | U5: - Age Segment: relabeled from source categories ('Teenager'/'Adult'/'Senior') to actual age ranges (18-29 / 30-49 / 50+), since the original labels were misleading (the 'Teenager' bucket included ages up to 29).
A6: 5 | B6: 403-9293516-4577154 | C6: 9293516 | D6: Men | E6: 62 | F6: 50+ | G6: 45299 | H6: Jan | I6: Delivered | J6: End User | K6: QNT | L6: Isolate | M6: 1KG | N6: 8 | O6: INR | P6: 6500 | Q6: Gurugram | R6: =IF(I6="Delivered",P6,0) -> 6500 | S6: =IF(COUNTIF($C$2:$C$1501,C6)>1,"Repeat","One-Time") -> One-Time | U6: - Net Revenue: Amount is counted only for orders with status 'Delivered'; Cancelled/Refunded/Returned orders are excluded from realized revenue but retained in the dataset for loss analysis.
A7: 6 | B7: 407-1298130-0368305 | C7: 1298130 | D7: Men | E7: 49 | F7: 30-49 | G7: 45300 | H7: Jan | I7: Delivered | J7: End User | K7: GNC | L7: Isolate | M7: 2KG | N7: 4 | O7: INR | P7: 6500 | Q7: Sangli Miraj Kupwad | R7: =IF(I7="Delivered",P7,0) -> 6500 | S7: =IF(COUNTIF($C$2:$C$1501,C7)>1,"Repeat","One-Time") -> Repeat | U7: - Order ID is not a unique key in the source data (some IDs repeat across different dates/amounts for the same customer); each row is treated as one transaction line for counting purposes.
A8: 7 | B8: 407-1298130-0368305 | C8: 1298130 | D8: Men | E8: 23 | F8: 18-29 | G8: 45301 | H8: Jan | I8: Delivered | J8: End User | K8: Nroute | L8: Isolate | M8: 2KG | N8: 6 | O8: INR | P8: 6500 | Q8: Bengaluru | R8: =IF(I8="Delivered",P8,0) -> 6500 | S8: =IF(COUNTIF($C$2:$C$1501,C8)>1,"Repeat","One-Time") -> Repeat
A9: 8 | B9: 171-5561216-3398711 | C9: 5561216 | D9: Men | E9: 70 | F9: 50+ | G9: 45302 | H9: Jan | I9: Delivered | J9: End User | K9: Steadfast Nutrition | L9: Isolate | M9: 2KG | N9: 5 | O9: INR | P9: 7500 | Q9: Gurugram | R9: =IF(I9="Delivered",P9,0) -> 7500 | S9: =IF(COUNTIF($C$2:$C$1501,C9)>1,"Repeat","One-Time") -> One-Time
A10: 9 | B10: 408-2935263-2935550 | C10: 2935263 | D10: Men | E10: 75 | F10: 50+ | G10: 45303 | H10: Jan | I10: Delivered | J10: End User | K10: MuscleBlaze | L10: Isolate | M10: 2KG | N10: 23 | O10: INR | P10: 7500 | Q10: Bengaluru | R10: =IF(I10="Delivered",P10,0) -> 7500 | S10: =IF(COUNTIF($C$2:$C$1501,C10)>1,"Repeat","One-Time") -> One-Time
A11: 10 | B11: 404-2648970-9042715 | C11: 2648970 | D11: Men | E11: 43 | F11: 30-49 | G11: 45304 | H11: Jan | I11: Delivered | J11: End User | K11: Avatar | L11: Isolate | M11: 2KG | N11: 2 | O11: INR | P11: 7500 | Q11: Vijayawada | R11: =IF(I11="Delivered",P11,0) -> 7500 | S11: =IF(COUNTIF($C$2:$C$1501,C11)>1,"Repeat","One-Time") -> Repeat
A12: 11 | B12: 404-2648970-9042715 | C12: 2648970 | D12: Men | E12: 76 | F12: 50+ | G12: 45305 | H12: Jan | I12: Delivered | J12: End User | K12: As It Is | L12: Isolate | M12: 2KG | N12: 5 | O12: INR | P12: 7500 | Q12: Thiruvananthapuram | R12: =IF(I12="Delivered",P12,0) -> 7500 | S12: =IF(COUNTIF($C$2:$C$1501,C12)>1,"Repeat","One-Time") -> Repeat
A13: 12 | B13: 404-2648970-9042715 | C13: 2648970 | D13: Men | E13: 45 | F13: 30-49 | G13: 45306 | H13: Jan | I13: Delivered | J13: End User | K13: Proquest | L13: Isolate | M13: 2KG | N13: 9 | O13: INR | P13: 7500 | Q13: Arakonam | R13: =IF(I13="Delivered",P13,0) -> 7500 | S13: =IF(COUNTIF($C$2:$C$1501,C13)>1,"Repeat","One-Time") -> Repeat
A14: 13 | B14: 408-0265357-4939534 | C14: 265357 | D14: Men | E14: 18 | F14: 18-29 | G14: 45307 | H14: Jan | I14: Delivered | J14: End User | K14: Proquest | L14: Isolate | M14: 2KG | N14: 27 | O14: INR | P14: 7500 | Q14: Guwahati | R14: =IF(I14="Delivered",P14,0) -> 7500 | S14: =IF(COUNTIF($C$2:$C$1501,C14)>1,"Repeat","One-Time") -> One-Time
A15: 14 | B15: 403-9268874-7296313 | C15: 9268874 | D15: Men | E15: 44 | F15: 30-49 | G15: 45308 | H15: Jan | I15: Delivered | J15: End User | K15: Proquest | L15: Isolate | M15: 2KG | N15: 6 | O15: INR | P15: 7500 | Q15: Bengaluru | R15: =IF(I15="Delivered",P15,0) -> 7500 | S15: =IF(COUNTIF($C$2:$C$1501,C15)>1,"Repeat","One-Time") -> One-Time
A16: 15 | B16: 407-0442660-2736366 | C16: 442660 | D16: Men | E16: 52 | F16: 50+ | G16: 45309 | H16: Jan | I16: Delivered | J16: End User | K16: Proquest | L16: Isolate | M16: 2KG | N16: 6 | O16: INR | P16: 7500 | Q16: Hyderabad | R16: =IF(I16="Delivered",P16,0) -> 7500 | S16: =IF(COUNTIF($C$2:$C$1501,C16)>1,"Repeat","One-Time") -> One-Time
A17: 16 | B17: 406-7482261-1657136 | C17: 7482261 | D17: Men | E17: 18 | F17: 18-29 | G17: 45310 | H17: Jan | I17: Delivered | J17: End User | K17: Proquest | L17: Isolate | M17: 2KG | N17: 2 | O17: INR | P17: 5800 | Q17: New Delhi | R17: =IF(I17="Delivered",P17,0) -> 5800 | S17: =IF(COUNTIF($C$2:$C$1501,C17)>1,"Repeat","One-Time") -> One-Time
A18: 17 | B18: 407-7039962-7080347 | C18: 7039962 | D18: Men | E18: 30 | F18: 30-49 | G18: 45326 | H18: Feb | I18: Delivered | J18: End User | K18: Proquest | L18: Isolate | M18: 2KG | N18: 32 | O18: INR | P18: 5800 | Q18: Bhubaneswar | R18: =IF(I18="Delivered",P18,0) -> 5800 | S18: =IF(COUNTIF($C$2:$C$1501,C18)>1,"Repeat","One-Time") -> One-Time
A19: 18 | B19: 407-3422488-7373923 | C19: 3422488 | D19: Men | E19: 48 | F19: 30-49 | G19: 45326 | H19: Feb | I19: Delivered | J19: End User | K19: Big Muscle | L19: Isolate | M19: 2KG | N19: 3 | O19: INR | P19: 5800 | Q19: Sirohi | R19: =IF(I19="Delivered",P19,0) -> 5800 | S19: =IF(COUNTIF($C$2:$C$1501,C19)>1,"Repeat","One-Time") -> One-Time
... A1501: 1500 | B1501: 405-0271059-1293107 | C1501: 271059 | D1501: Women | E1501: 34 | F1501: 30-49 | G1501: 45379 | H1501: Mar | I1501: Delivered | J1501: Gym Pro Shop | K1501: Proquest | L1501: Isolate | M1501: 2KG | N1501: 65 | O1501: INR | P1501: 6600 | Q1501: Gurugram | R1501: =IF(I1501="Delivered",P1501,0) -> 6600 | S1501: =IF(COUNTIF($C$2:$C$1501,C1501)>1,"Repeat","One-Time") -> Repeat
